Workbook

Sheet Dashboard
A1: 📊 DASHBOARD GLOBAL - CONTROL GENERAL DE CRÉDITOS NATILLERA
A2: Administrador: Santiago | Información Consolidada en Tiempo Real | Haz clic en cualquier socio para ir directo a su pestaña
A4: FECHA DE HOY | C4: TOTAL PRESTADO | D4: CAPITAL EN LA CALLE | E4: INTERESES LIQUIDADOS | F4: INTERESES POR COBRAR | G4: TOTAL POR COBRAR HOY | I4: TOTAL RECAUDADO EN ABONOS
A5: =TODAY() | C5: =C29 | D5: =D29 | E5: =E29 | F5: =F29 | G5: =G29 | I5: =H29
A7: 👥 CONSOLIDADO DE SOCIOS Y ESTADO DE CUENTA GENERAL
A9: N° | B9: Socio / Nombre de la Pestaña | C9: Capital Prestado | D9: Capital en Calle | E9: Intereses Liquidados | F9: Intereses por Cobrar | G9: Total por Cobrar | H9: Total Abonado | I9: Estado Socio | J9: N° Créditos | K9: Acceso Directo
A10: 1 | B10: =HYPERLINK("#'Jorge Gaviria'!A1", "Jorge Gaviria") | C10: ='Jorge Gaviria'!D5 | D10: ='Jorge Gaviria'!F5 | E10: ='Jorge Gaviria'!H5 | F10: ='Jorge Gaviria'!J5 | G10: ='Jorge Gaviria'!L5 | H10: ='Jorge Gaviria'!U5 | I10: =IF(OR(C10="",C10=0),"",IF(G10<=0,"PAZ Y SALVO",IF(D10>0,"CON DEUDA","AL DÍA"))) | J10: =COUNT('Jorge Gaviria'!F9:F28) | K10: =HYPERLINK("#'Jorge Gaviria'!A1", "👉 Ver Créditos")
A11: 2 | B11: =HYPERLINK("#'Caro Rios'!A1", "Caro Rios") | C11: ='Caro Rios'!D5 | D11: ='Caro Rios'!F5 | E11: ='Caro Rios'!H5 | F11: ='Caro Rios'!J5 | G11: ='Caro Rios'!L5 | H11: ='Caro Rios'!U5 | I11: =IF(OR(C11="",C11=0),"",IF(G11<=0,"PAZ Y SALVO",IF(D11>0,"CON DEUDA","AL DÍA"))) | J11: =COUNT('Caro Rios'!F9:F28) | K11: =HYPERLINK("#'Caro Rios'!A1", "👉 Ver Créditos")
A12: 3 | B12: =HYPERLINK("#'Andres Castro'!A1", "Andres Castro") | C12: ='Andres Castro'!D5 | D12: ='Andres Castro'!F5 | E12: ='Andres Castro'!H5 | F12: ='Andres Castro'!J5 | G12: ='Andres Castro'!L5 | H12: ='Andres Castro'!U5 | I12: =IF(OR(C12="",C12=0),"",IF(G12<=0,"PAZ Y SALVO",IF(D12>0,"CON DEUDA","AL DÍA"))) | J12: =COUNT('Andres Castro'!F9:F18) | K12: =HYPERLINK("#'Andres Castro'!A1", "👉 Ver Créditos")
A13: 4 | B13: =HYPERLINK("#'Wilson Alvarez'!A1", "Wilson Alvarez") | C13: ='Wilson Alvarez'!D5 | D13: ='Wilson Alvarez'!F5 | E13: ='Wilson Alvarez'!H5 | F13: ='Wilson Alvarez'!J5 | G13: ='Wilson Alvarez'!L5 | H13: ='Wilson Alvarez'!U5 | I13: =IF(OR(C13="",C13=0),"",IF(G13<=0,"PAZ Y SALVO",IF(D13>0,"CON DEUDA","AL DÍA"))) | J13: =COUNT('Wilson Alvarez'!F9:F18) | K13: =HYPERLINK("#'Wilson Alvarez'!A1", "👉 Ver Créditos")
A14: 5
A15: 6
A16: 7
A17: 8
A18: 9
A19: 10
A20: 11
A21: 12
A22: 13
A23: 14
A24: 15
A25: 16
... A28: 19
A29: TOTAL GENERAL NATILLERA | C29: =SUM(C10:C28) | D29: =SUM(D10:D28) | E29: =SUM(E10:E28) | F29: =SUM(F10:F28) | G29: =SUM(G10:G28) | H29: =SUM(H10:H28)
A32: 💡 GUÍA PARA SANTIAGO: CÓMO USAR EL DASHBOARD Y AGREGAR NUEVAS PERSONAS
A33: ✔ | B33: 1. Navegación con 1 Clic: Haz clic en '👉 Ver Créditos' o sobre el nombre de Jorge, Caro, Andrés o Wilson para ir directo a su pestaña. No tienes que buscar entre pestañas manualmente.
A34: ✔ | B34: 2. Cómo Agregar una Nueva Persona: Abajo en las pestañas, dale clic derecho a 'Formato Credito Natillera' ➔ 'Mover o copiar...' ➔ marca 'Crear una copia'. Ponle el nombre del nuevo socio a la pestaña.
A35: ✔ | B35: 3. Vincular al Dashboard: En la siguiente fila vacía del Dashboard (por ejemplo fila 14), escribe su nombre y enlázalo escribiendo ='Nuevo Socio'!D5 en Capital Prestado. ¡El Dashboard consolidará todo solo!
A36: ✔ | B36: 4. Información 100% en Vivo: Cada vez que abras el Excel, la celda =HOY() recalculará los días y los intereses al día de hoy, y los créditos cancelados mantendrán sus intereses congelados a la fecha de pago.

Sheet Jorge Gaviria
A1: 💰 SISTEMA DE CONTROL DE CRÉDITOS, INTERESES CONGELADOS A FECHA DE PAGO Y ABONOS - NATILLERA
A2: Administrador: Santiago | Actualización Automática con =HOY() | Los intereses se congelan a la Fecha de Pago para no seguir acumulando cobros
B3: =HYPERLINK("#Dashboard!A1", "⬅ VOLVER AL DASHBOARD GLOBAL")
B4: FECHA DE HOY | D4: TOTAL PRESTADO | F4: CAPITAL EN LA CALLE | H4: INTERESES A FECHA DE PAGO | J4: INTERESES POR COBRAR | L4: TOTAL POR COBRAR GENERAL | Q4: ABONOS A INTERÉS | S4: ABONOS A CAPITAL | U4: TOTAL RECAUDADO EN ABONOS
B5: =TODAY() | D5: =F29 | F5: =M29 | H5: =I29 | J5: =K29 | L5: =N29 | Q5: =J29 | S5: =L29 | U5: =Q5+S5
A7: 📋 TABLA DE CRÉDITOS Y LIQUIDACIÓN (Con congelamiento de intereses a la fecha de pago) | Q7: 💳 REGISTRO DE ABONOS RECIBIDOS (Permite múltiples pagos por crédito)
A8: N° | B8: Nombre del Socio / Deudor | C8: Fecha Crédito | D8: Fecha Pago / Liquidación | E8: Días | F8: Valor Crédito (Capital) | G8: Tasa Mes | H8: Intereses a Hoy (En Vivo) | I8: Intereses a Fecha Pago | J8: Total Abono Interés | K8: Saldo Interés | L8: Total Abono Capital | M8: Saldo Capital | N8: Total a Pagar Hoy | O8: Estado | Q8: Fecha Pago | R8: N° Crédito | S8: Socio (Automático) | T8: Abono a Intereses | U8: Abono a Capital | V8: Total Abonado | W8: Medio / Comprobante
A9: 1 | B9: Jorge Gaviria | C9: 46042 | D9: 46188 | E9: =IF(C9="","",IF(D9<>"",D9-C9,TODAY()-C9)) | F9: 500000 | G9: 0.005 | H9: =IF(F9="","",ROUND(F9*(G9/30)*(TODAY()-C9),0)) | I9: =IF(F9="","",IF(D9<>"",ROUND(F9*(G9/30)*(D9-C9),0),"-")) | J9: =IF(F9="","",SUMIF(R$9:R$40, A9, T$9:T$40)) | K9: =IF(F9="","",MAX(0,IF(D9<>"",I9,H9)-J9)) | L9: =IF(F9="","",SUMIF(R$9:R$40, A9, U$9:U$40)) | M9: =IF(F9="","",MAX(0,F9-L9)) | N9: =IF(F9="","",K9+M9) | O9: =IF(F9="","",IF(N9<=0,"PAGADO",IF(D9<>"","PAGADO",IF(E9>30,"PENDIENTE","VIGENTE")))) | Q9: 46188 | R9: 1 | S9: =IF(R9="","",IFERROR(VLOOKUP(R9, A$9:B$28, 2, FALSE), "No existe")) | T9: 12167 | U9: 500000 | V9: =IF(R9="","",T9+U9) | W9: Consignacion de $3,000,000 se liquidan creditos viejos de capital e intereses
A10: 2 | B10: Jorge Gaviria | C10: 46058 | D10: 46188 | E10: =IF(C10="","",IF(D10<>"",D10-C10,TODAY()-C10)) | F10: 200000 | G10: 0.005 | H10: =IF(F10="","",ROUND(F10*(G10/30)*(TODAY()-C10),0)) | I10: =IF(F10="","",IF(D10<>"",ROUND(F10*(G10/30)*(D10-C10),0),"-")) | J10: =IF(F10="","",SUMIF(R$9:R$40, A10, T$9:T$40)) | K10: =IF(F10="","",MAX(0,IF(D10<>"",I10,H10)-J10)) | L10: =IF(F10="","",SUMIF(R$9:R$40, A10, U$9:U$40)) | M10: =IF(F10="","",MAX(0,F10-L10)) | N10: =IF(F10="","",K10+M10) | O10: =IF(F10="","",IF(N10<=0,"PAGADO",IF(D10<>"","PAGADO",IF(E10>30,"PENDIENTE","VIGENTE")))) | Q10: 46188 | R10: 2 | S10: =IF(R10="","",IFERROR(VLOOKUP(R10, A$9:B$28, 2, FALSE), "No existe")) | T10: 4333 | U10: 200000 | V10: =IF(R10="","",T10+U10)
A11: 3 | B11: Jorge Gaviria | C11: 46059 | D11: 46188 | E11: =IF(C11="","",IF(D11<>"",D11-C11,TODAY()-C11)) | F11: 300000 | G11: 0.005 | H11: =IF(F11="","",ROUND(F11*(G11/30)*(TODAY()-C11),0)) | I11: =IF(F11="","",IF(D11<>"",ROUND(F11*(G11/30)*(D11-C11),0),"-")) | J11: =IF(F11="","",SUMIF(R$9:R$40, A11, T$9:T$40)) | K11: =IF(F11="","",MAX(0,IF(D11<>"",I11,H11)-J11)) | L11: =IF(F11="","",SUMIF(R$9:R$40, A11, U$9:U$40)) | M11: =IF(F11="","",MAX(0,F11-L11)) | N11: =IF(F11="","",K11+M11) | O11: =IF(F11="","",IF(N11<=0,"PAGADO",IF(D11<>"","PAGADO",IF(E11>30,"PENDIENTE","VIGENTE")))) | Q11: 46188 | R11: 3 | S11: =IF(R11="","",IFERROR(VLOOKUP(R11, A$9:B$28, 2, FALSE), "No existe")) | T11: 6450 | U11: 300000 | V11: =IF(R11="","",T11+U11)
A12: 4 | B12: Jorge Gaviria | C12: 46069 | D12: 46188 | E12: =IF(C12="","",IF(D12<>"",D12-C12,TODAY()-C12)) | F12: 500000 | G12: 0.005 | H12: =IF(F12="","",ROUND(F12*(G12/30)*(TODAY()-C12),0)) | I12: =IF(F12="","",IF(D12<>"",ROUND(F12*(G12/30)*(D12-C12),0),"-")) | J12: =IF(F12="","",SUMIF(R$9:R$40, A12, T$9:T$40)) | K12: =IF(F12="","",MAX(0,IF(D12<>"",I12,H12)-J12)) | L12: =IF(F12="","",SUMIF(R$9:R$40, A12, U$9:U$40)) | M12: =IF(F12="","",MAX(0,F12-L12)) | N12: =IF(F12="","",K12+M12) | O12: =IF(F12="","",IF(N12<=0,"PAGADO",IF(D12<>"","PAGADO",IF(E12>30,"PENDIENTE","VIGENTE")))) | Q12: 46188 | R12: 4 | S12: =IF(R12="","",IFERROR(VLOOKUP(R12, A$9:B$28, 2, FALSE), "No existe")) | T12: 9917 | U12: 500000 | V12: =IF(R12="","",T12+U12)
A13: 5 | B13: Jorge Gaviria | C13: 46087 | D13: 46188 | E13: =IF(C13="","",IF(D13<>"",D13-C13,TODAY()-C13)) | F13: 200000 | G13: 0.005 | H13: =IF(F13="","",ROUND(F13*(G13/30)*(TODAY()-C13),0)) | I13: =IF(F13="","",IF(D13<>"",ROUND(F13*(G13/30)*(D13-C13),0),"-")) | J13: =IF(F13="","",SUMIF(R$9:R$40, A13, T$9:T$40)) | K13: =IF(F13="","",MAX(0,IF(D13<>"",I13,H13)-J13)) | L13: =IF(F13="","",SUMIF(R$9:R$40, A13, U$9:U$40)) | M13: =IF(F13="","",MAX(0,F13-L13)) | N13: =IF(F13="","",K13+M13) | O13: =IF(F13="","",IF(N13<=0,"PAGADO",IF(D13<>"","PAGADO",IF(E13>30,"PENDIENTE","VIGENTE")))) | Q13: 46188 | R13: 5 | S13: =IF(R13="","",IFERROR(VLOOKUP(R13, A$9:B$28, 2, FALSE), "No existe")) | T13: 3367 | U13: 200000 | V13: =IF(R13="","",T13+U13)
A14: 6 | B14: Jorge Gaviria | C14: 46112 | D14: 46188 | E14: =IF(C14="","",IF(D14<>"",D14-C14,TODAY()-C14)) | F14: 1000000 | G14: 0.005 | H14: =IF(F14="","",ROUND(F14*(G14/30)*(TODAY()-C14),0)) | I14: =IF(F14="","",IF(D14<>"",ROUND(F14*(G14/30)*(D14-C14),0),"-")) | J14: =IF(F14="","",SUMIF(R$9:R$40, A14, T$9:T$40)) | K14: =IF(F14="","",MAX(0,IF(D14<>"",I14,H14)-J14)) | L14: =IF(F14="","",SUMIF(R$9:R$40, A14, U$9:U$40)) | M14: =IF(F14="","",MAX(0,F14-L14)) | N14: =IF(F14="","",K14+M14) | O14: =IF(F14="","",IF(N14<=0,"PAGADO",IF(D14<>"","PAGADO",IF(E14>30,"PENDIENTE","VIGENTE")))) | Q14: 46188 | R14: 6 | S14: =IF(R14="","",IFERROR(VLOOKUP(R14, A$9:B$28, 2, FALSE), "No existe")) | T14: 12667 | U14: 1000000 | V14: =IF(R14="","",T14+U14)
A15: 7 | B15: Jorge Gaviria | C15: 46138 | D15: 46188 | E15: =IF(C15="","",IF(D15<>"",D15-C15,TODAY()-C15)) | F15: 100000 | G15: 0.005 | H15: =IF(F15="","",ROUND(F15*(G15/30)*(TODAY()-C15),0)) | I15: =IF(F15="","",IF(D15<>"",ROUND(F15*(G15/30)*(D15-C15),0),"-")) | J15: =IF(F15="","",SUMIF(R$9:R$40, A15, T$9:T$40)) | K15: =IF(F15="","",MAX(0,IF(D15<>"",I15,H15)-J15)) | L15: =IF(F15="","",SUMIF(R$9:R$40, A15, U$9:U$40)) | M15: =IF(F15="","",MAX(0,F15-L15)) | N15: =IF(F15="","",K15+M15) | O15: =IF(F15="","",IF(N15<=0,"PAGADO",IF(D15<>"","PAGADO",IF(E15>30,"PENDIENTE","VIGENTE")))) | Q15: 46188 | R15: 7 | S15: =IF(R15="","",IFERROR(VLOOKUP(R15, A$9:B$28, 2, FALSE), "No existe")) | T15: 833 | U15: 100000 | V15: =IF(R15="","",T15+U15)
A16: 8 | B16: Jorge Gaviria | C16: 46143 | D16: 46231 | E16: =IF(C16="","",IF(D16<>"",D16-C16,TODAY()-C16)) | F16: 1200000 | G16: 0.005 | H16: =IF(F16="","",ROUND(F16*(G16/30)*(TODAY()-C16),0)) | I16: =IF(F16="","",IF(D16<>"",ROUND(F16*(G16/30)*(D16-C16),0),"-")) | J16: =IF(F16="","",SUMIF(R$9:R$40, A16, T$9:T$40)) | K16: =IF(F16="","",MAX(0,IF(D16<>"",I16,H16)-J16)) | L16: =IF(F16="","",SUMIF(R$9:R$40, A16, U$9:U$40)) | M16: =IF(F16="","",MAX(0,F16-L16)) | N16: =IF(F16="","",K16+M16) | O16: =IF(F16="","",IF(N16<=0,"PAGADO",IF(D16<>"","PAGADO",IF(E16>30,"PENDIENTE","VIGENTE")))) | Q16: 46188 | R16: 8 | S16: =IF(R16="","",IFERROR(VLOOKUP(R16, A$9:B$28, 2, FALSE), "No existe")) | T16: 0 | U16: 150266 | V16: =IF(R16="","",T16+U16)
A17: 9 | B17: Jorge Gaviria | C17: 46212 | D17: 46276 | E17: =IF(C17="","",IF(D17<>"",D17-C17,TODAY()-C17)) | F17: 1000000 | G17: 0.005 | H17: =IF(F17="","",ROUND(F17*(G17/30)*(TODAY()-C17),0)) | I17: =IF(F17="","",IF(D17<>"",ROUND(F17*(G17/30)*(D17-C17),0),"-")) | J17: =IF(F17="","",SUMIF(R$9:R$40, A17, T$9:T$40)) | K17: =IF(F17="","",MAX(0,IF(D17<>"",I17,H17)-J17)) | L17: =IF(F17="","",SUMIF(R$9:R$40, A17, U$9:U$40)) | M17: =IF(F17="","",MAX(0,F17-L17)) | N17: =IF(F17="","",K17+M17) | O17: =IF(F17="","",IF(N17<=0,"PAGADO",IF(D17<>"","PAGADO",IF(E17>30,"PENDIENTE","VIGENTE")))) | Q17: 46231 | R17: 8 | S17: =IF(R17="","",IFERROR(VLOOKUP(R17, A$9:B$28, 2, FALSE), "No existe")) | T17: 17600 | U17: 1049734 | V17: =IF(R17="","",T17+U17) | W17: Consignacion de $1,200,000 se liquidan creditos viejos de capital e interes
A18: 10 | B18: Jorge Gaviria | C18: 46212 | D18: 46276 | E18: =IF(C18="","",IF(D18<>"",D18-C18,TODAY()-C18)) | F18: 700000 | G18: 0.005 | H18: =IF(F18="","",ROUND(F18*(G18/30)*(TODAY()-C18),0)) | I18: =IF(F18="","",IF(D18<>"",ROUND(F18*(G18/30)*(D18-C18),0),"-")) | J18: =IF(F18="","",SUMIF(R$9:R$40, A18, T$9:T$40)) | K18: =IF(F18="","",MAX(0,IF(D18<>"",I18,H18)-J18)) | L18: =IF(F18="","",SUMIF(R$9:R$40, A18, U$9:U$40)) | M18: =IF(F18="","",MAX(0,F18-L18)) | N18: =IF(F18="","",K18+M18) | O18: =IF(F18="","",IF(N18<=0,"PAGADO",IF(D18<>"","PAGADO",IF(E18>30,"PENDIENTE","VIGENTE")))) | Q18: 46231 | R18: 9 | S18: =IF(R18="","",IFERROR(VLOOKUP(R18, A$9:B$28, 2, FALSE), "No existe")) | T18: 0 | U18: 132166 | V18: =IF(R18="","",T18+U18)
A19: 11 | B19: Jorge Gaviria | C19: 46219 | D19: 46276 | E19: =IF(C19="","",IF(D19<>"",D19-C19,TODAY()-C19)) | F19: 1000000 | G19: 0.005 | H19: =IF(F19="","",ROUND(F19*(G19/30)*(TODAY()-C19),0)) | I19: =IF(F19="","",IF(D19<>"",ROUND(F19*(G19/30)*(D19-C19),0),"-")) | J19: =IF(F19="","",SUMIF(R$9:R$40, A19, T$9:T$40)) | K19: =IF(F19="","",MAX(0,IF(D19<>"",I19,H19)-J19)) | L19: =IF(F19="","",SUMIF(R$9:R$40, A19, U$9:U$40)) | M19: =IF(F19="","",MAX(0,F19-L19)) | N19: =IF(F19="","",K19+M19) | O19: =IF(F19="","",IF(N19<=0,"PAGADO",IF(D19<>"","PAGADO",IF(E19>30,"PENDIENTE","VIGENTE")))) | Q19: 46276 | R19: 9 | S19: =IF(R19="","",IFERROR(VLOOKUP(R19, A$9:B$28, 2, FALSE), "No existe")) | T19: 10667 | U19: 867834 | V19: =IF(R19="","",T19+U19) | W19: Consignacion de $3,500,000 se liquidan creditos viejos de capital e intereses
A20: 12 | B20: Jorge Gaviria | C20: 46262 | E20: =IF(C20="","",IF(D20<>"",D20-C20,TODAY()-C20)) | F20: 1000000 | G20: 0.005 | H20: =IF(F20="","",ROUND(F20*(G20/30)*(TODAY()-C20),0)) | I20: =IF(F20="","",IF(D20<>"",ROUND(F20*(G20/30)*(D20-C20),0),"-")) | J20: =IF(F20="","",SUMIF(R$9:R$40, A20, T$9:T$40)) | K20: =IF(F20="","",MAX(0,IF(D20<>"",I20,H20)-J20)) | L20: =IF(F20="","",SUMIF(R$9:R$40, A20, U$9:U$40)) | M20: =IF(F20="","",MAX(0,F20-L20)) | N20: =IF(F20="","",K20+M20) | O20: =IF(F20="","",IF(N20<=0,"PAGADO",IF(D20<>"","PAGADO",IF(E20>30,"PENDIENTE","VIGENTE")))) | Q20: 46276 | R20: 10 | S20: =IF(R20="","",IFERROR(VLOOKUP(R20, A$9:B$28, 2, FALSE), "No existe")) | T20: 7467 | U20: 700000 | V20: =IF(R20="","",T20+U20)
A21: 13 | B21: Jorge Gaviria | C21: 46295 | E21: =IF(C21="","",IF(D21<>"",D21-C21,TODAY()-C21)) | F21: 1000000 | G21: 0.005 | H21: =IF(F21="","",ROUND(F21*(G21/30)*(TODAY()-C21),0)) | I21: =IF(F21="","",IF(D21<>"",ROUND(F21*(G21/30)*(D21-C21),0),"-")) | J21: =IF(F21="","",SUMIF(R$9:R$40, A21, T$9:T$40)) | K21: =IF(F21="","",MAX(0,IF(D21<>"",I21,H21)-J21)) | L21: =IF(F21="","",SUMIF(R$9:R$40, A21, U$9:U$40)) | M21: =IF(F21="","",MAX(0,F21-L21)) | N21: =IF(F21="","",K21+M21) | O21: =IF(F21="","",IF(N21<=0,"PAGADO",IF(D21<>"","PAGADO",IF(E21>30,"PENDIENTE","VIGENTE")))) | Q21: 46276 | R21: 11 | S21: =IF(R21="","",IFERROR(VLOOKUP(R21, A$9:B$28, 2, FALSE), "No existe")) | T21: 9500 | U21: 1000000 | V21: =IF(R21="","",T21+U21)
A22: 14 | E22: =IF(C22="","",IF(D22<>"",D22-C22,TODAY()-C22)) | G22: 0.005 | H22: =IF(F22="","",ROUND(F22*(G22/30)*(TODAY()-C22),0)) | I22: =IF(F22="","",IF(D22<>"",ROUND(F22*(G22/30)*(D22-C22),0),"-")) | J22: =IF(F22="","",SUMIF(R$9:R$40, A22, T$9:T$40)) | K22: =IF(F22="","",MAX(0,IF(D22<>"",I22,H22)-J22)) | L22: =IF(F22="","",SUMIF(R$9:R$40, A22, U$9:U$40)) | M22: =IF(F22="","",MAX(0,F22-L22)) | N22: =IF(F22="","",K22+M22) | O22: =IF(F22="","",IF(N22<=0,"PAGADO",IF(D22<>"","PAGADO",IF(E22>30,"PENDIENTE","VIGENTE")))) | Q22: 46276 | R22: 12 | S22: =IF(R22="","",IFERROR(VLOOKUP(R22, A$9:B$28, 2, FALSE), "No existe")) | T22: 0 | U22: 904532 | V22: =IF(R22="","",T22+U22)
A23: 15 | E23: =IF(C23="","",IF(D23<>"",D23-C23,TODAY()-C23)) | G23: 0.005 | H23: =IF(F23="","",ROUND(F23*(G23/30)*(TODAY()-C23),0)) | I23: =IF(F23="","",IF(D23<>"",ROUND(F23*(G23/30)*(D23-C23),0),"-")) | J23: =IF(F23="","",SUMIF(R$9:R$40, A23, T$9:T$40)) | K23: =IF(F23="","",MAX(0,IF(D23<>"",I23,H23)-J23)) | L23: =IF(F23="","",SUMIF(R$9:R$40, A23, U$9:U$40)) | M23: =IF(F23="","",MAX(0,F23-L23)) | N23: =IF(F23="","",K23+M23) | O23: =IF(F23="","",IF(N23<=0,"PAGADO",IF(D23<>"","PAGADO",IF(E23>30,"PENDIENTE","VIGENTE")))) | S23: =IF(R23="","",IFERROR(VLOOKUP(R23, A$9:B$28, 2, FALSE), "No existe")) | V23: =IF(R23="","",T23+U23)
A24: 16 | E24: =IF(C24="","",IF(D24<>"",D24-C24,TODAY()-C24)) | G24: 0.005 | H24: =IF(F24="","",ROUND(F24*(G24/30)*(TODAY()-C24),0)) | I24: =IF(F24="","",IF(D24<>"",ROUND(F24*(G24/30)*(D24-C24),0),"-")) | J24: =IF(F24="","",SUMIF(R$9:R$40, A24, T$9:T$40)) | K24: =IF(F24="","",MAX(0,IF(D24<>"",I24,H24)-J24)) | L24: =IF(F24="","",SUMIF(R$9:R$40, A24, U$9:U$40)) | M24: =IF(F24="","",MAX(0,F24-L24)) | N24: =IF(F24="","",K24+M24) | O24: =IF(F24="","",IF(N24<=0,"PAGADO",IF(D24<>"","PAGADO",IF(E24>30,"PENDIENTE","VIGENTE")))) | S24: =IF(R24="","",IFERROR(VLOOKUP(R24, A$9:B$28, 2, FALSE), "No existe")) | V24: =IF(R24="","",T24+U24)
A25: 17 | E25: =IF(C25="","",IF(D25<>"",D25-C25,TODAY()-C25)) | G25: 0.005 | H25: =IF(F25="","",ROUND(F25*(G25/30)*(TODAY()-C25),0)) | I25: =IF(F25="","",IF(D25<>"",ROUND(F25*(G25/30)*(D25-C25),0),"-")) | J25: =IF(F25="","",SUMIF(R$9:R$40, A25, T$9:T$40)) | K25: =IF(F25="","",MAX(0,IF(D25<>"",I25,H25)-J25)) | L25: =IF(F25="","",SUMIF(R$9:R$40, A25, U$9:U$40)) | M25: =IF(F25="","",MAX(0,F25-L25)) | N25: =IF(F25="","",K25+M25) | O25: =IF(F25="","",IF(N25<=0,"PAGADO",IF(D25<>"","PAGADO",IF(E25>30,"PENDIENTE","VIGENTE")))) | S25: =IF(R25="","",IFERROR(VLOOKUP(R25, A$9:B$28, 2, FALSE), "No existe")) | V25: =IF(R25="","",T25+U25)
A26: 18 | E26: =IF(C26="","",IF(D26<>"",D26-C26,TODAY()-C26)) | G26: 0.005 | H26: =IF(F26="","",ROUND(F26*(G26/30)*(TODAY()-C26),0)) | I26: =IF(F26="","",IF(D26<>"",ROUND(F26*(G26/30)*(D26-C26),0),"-")) | J26: =IF(F26="","",SUMIF(R$9:R$40, A26, T$9:T$40)) | K26: =IF(F26="","",MAX(0,IF(D26<>"",I26,H26)-J26)) | L26: =IF(F26="","",SUMIF(R$9:R$40, A26, U$9:U$40)) | M26: =IF(F26="","",MAX(0,F26-L26)) | N26: =IF(F26="","",K26+M26) | O26: =IF(F26="","",IF(N26<=0,"PAGADO",IF(D26<>"","PAGADO",IF(E26>30,"PENDIENTE","VIGENTE")))) | S26: =IF(R26="","",IFERROR(VLOOKUP(R26, A$9:B$28, 2, FALSE), "No existe")) | V26: =IF(R26="","",T26+U26)
A27: 19 | E27: =IF(C27="","",IF(D27<>"",D27-C27,TODAY()-C27)) | G27: 0.005 | H27: =IF(F27="","",ROUND(F27*(G27/30)*(TODAY()-C27),0)) | I27: =IF(F27="","",IF(D27<>"",ROUND(F27*(G27/30)*(D27-C27),0),"-")) | J27: =IF(F27="","",SUMIF(R$9:R$40, A27, T$9:T$40)) | K27: =IF(F27="","",MAX(0,IF(D27<>"",I27,H27)-J27)) | L27: =IF(F27="","",SUMIF(R$9:R$40, A27, U$9:U$40)) | M27: =IF(F27="","",MAX(0,F27-L27)) | N27: =IF(F27="","",K27+M27) | O27: =IF(F27="","",IF(N27<=0,"PAGADO",IF(D27<>"","PAGADO",IF(E27>30,"PENDIENTE","VIGENTE")))) | S27: =IF(R27="","",IFERROR(VLOOKUP(R27, A$9:B$28, 2, FALSE), "No existe")) | V27: =IF(R27="","",T27+U27)
A28: 20 | E28: =IF(C28="","",IF(D28<>"",D28-C28,TODAY()-C28)) | G28: 0.005 | H28: =IF(F28="","",ROUND(F28*(G28/30)*(TODAY()-C28),0)) | I28: =IF(F28="","",IF(D28<>"",ROUND(F28*(G28/30)*(D28-C28),0),"-")) | J28: =IF(F28="","",SUMIF(R$9:R$40, A28, T$9:T$40)) | K28: =IF(F28="","",MAX(0,IF(D28<>"",I28,H28)-J28)) | L28: =IF(F28="","",SUMIF(R$9:R$40, A28, U$9:U$40)) | M28: =IF(F28="","",MAX(0,F28-L28)) | N28: =IF(F28="","",K28+M28) | O28: =IF(F28="","",IF(N28<=0,"PAGADO",IF(D28<>"","PAGADO",IF(E28>30,"PENDIENTE","VIGENTE")))) | S28: =IF(R28="","",IFERROR(VLOOKUP(R28, A$9:B$28, 2, FALSE), "No existe")) | V28: =IF(R28="","",T28+U28)
A29: TOTAL GENERAL CRÉDITOS | F29: =SUM(F9:F28) | H29: =SUM(H9:H28) | I29: =SUM(I9:I28) | J29: =SUM(J9:J28) | K29: =SUM(K9:K28) | L29: =SUM(L9:L28) | M29: =SUM(M9:M28) | N29: =SUM(N9:N28) | S29: =IF(R29="","",IFERROR(VLOOKUP(R29, A$9:B$28, 2, FALSE), "No existe")) | V29: =IF(R29="","",T29+U29)
S30: =IF(R30="","",IFERROR(VLOOKUP(R30, A$9:B$28, 2, FALSE), "No existe")) | V30: =IF(R30="","",T30+U30)
S31: =IF(R31="","",IFERROR(VLOOKUP(R31, A$9:B$28, 2, FALSE), "No existe")) | V31: =IF(R31="","",T31+U31)
S32: =IF(R32="","",IFERROR(VLOOKUP(R32, A$9:B$28, 2, FALSE), "No existe")) | V32: =IF(R32="","",T32+U32)
S33: =IF(R33="","",IFERROR(VLOOKUP(R33, A$9:B$28, 2, FALSE), "No existe")) | V33: =IF(R33="","",T33+U33)
S34: =IF(R34="","",IFERROR(VLOOKUP(R34, A$9:B$28, 2, FALSE), "No existe")) | V34: =IF(R34="","",T34+U34)
S35: =IF(R35="","",IFERROR(VLOOKUP(R35, A$9:B$28, 2, FALSE), "No existe")) | V35: =IF(R35="","",T35+U35)
S36: =IF(R36="","",IFERROR(VLOOKUP(R36, A$9:B$28, 2, FALSE), "No existe")) | V36: =IF(R36="","",T36+U36)
S37: =IF(R37="","",IFERROR(VLOOKUP(R37, A$9:B$28, 2, FALSE), "No existe")) | V37: =IF(R37="","",T37+U37)
S38: =IF(R38="","",IFERROR(VLOOKUP(R38, A$9:B$28, 2, FALSE), "No existe")) | V38: =IF(R38="","",T38+U38)
S39: =IF(R39="","",IFERROR(VLOOKUP(R39, A$9:B$28, 2, FALSE), "No existe")) | V39: =IF(R39="","",T39+U39)
S40: =IF(R40="","",IFERROR(VLOOKUP(R40, A$9:B$28, 2, FALSE), "No existe")) | V40: =IF(R40="","",T40+U40)
Q41: TOTAL ABONOS REGISTRADOS | T41: =SUM(T9:T40) | U41: =SUM(U9:U40) | V41: =SUM(V9:V40)
...

Sheet Caro Rios
A1: 💰 SISTEMA DE CONTROL DE CRÉDITOS, INTERESES CONGELADOS A FECHA DE PAGO Y ABONOS - NATILLERA
A2: Administrador: Santiago | Actualización Automática con =HOY() | Los intereses se congelan a la Fecha de Pago para no seguir acumulando cobros
B3: =HYPERLINK("#Dashboard!A1", "⬅ VOLVER AL DASHBOARD GLOBAL")
B4: FECHA DE HOY | D4: TOTAL PRESTADO | F4: CAPITAL EN LA CALLE | H4: INTERESES A FECHA DE PAGO | J4: INTERESES POR COBRAR | L4: TOTAL POR COBRAR GENERAL | Q4: ABONOS A INTERÉS | S4: ABONOS A CAPITAL | U4: TOTAL RECAUDADO EN ABONOS
B5: =TODAY() | D5: =F29 | F5: =M29 | H5: =I29 | J5: =K29 | L5: =N29 | Q5: =I29 | S5: =L29 | U5: =Q5+S5
A7: 📋 TABLA DE CRÉDITOS Y LIQUIDACIÓN (Con congelamiento de intereses a la fecha de pago) | Q7: 💳 REGISTRO DE ABONOS RECIBIDOS (Permite múltiples pagos por crédito)
A8: N° | B8: Nombre del Socio / Deudor | C8: Fecha Crédito | D8: Fecha Pago / Liquidación | E8: Días | F8: Valor Crédito (Capital) | G8: Tasa Mes | H8: Intereses a Hoy (En Vivo) | I8: Intereses a Fecha Pago | J8: Total Abono Interés | K8: Saldo Interés | L8: Total Abono Capital | M8: Saldo Capital | N8: Total a Pagar Hoy | O8: Estado | Q8: Fecha Pago | R8: N° Crédito | S8: Socio (Automático) | T8: Abono a Intereses | U8: Abono a Capital | V8: Total Abonado | W8: Medio / Comprobante
A9: 1 | B9: Caro Rios | C9: 46072 | D9: 46098 | E9: =IF(C9="","",IF(D9<>"",D9-C9,TODAY()-C9)) | F9: 400000 | G9: 0.005 | H9: =IF(F9="","",ROUND(F9*(G9/30)*(TODAY()-C9),0)) | I9: =IF(F9="","",IF(D9<>"",ROUND(F9*(G9/30)*(D9-C9),0),"-")) | J9: =IF(F9="","",SUMIF(R$9:R$40, A9, T$9:T$40)) | K9: =IF(F9="","",MAX(0,IF(D9<>"",I9,H9)-J9)) | L9: =IF(F9="","",SUMIF(R$9:R$40, A9, U$9:U$40)) | M9: =IF(F9="","",MAX(0,F9-L9)) | N9: =IF(F9="","",K9+M9) | O9: =IF(F9="","",IF(N9<=0,"PAGADO",IF(D9<>"","PAGADO",IF(E9>30,"PENDIENTE","VIGENTE")))) | Q9: 46080 | R9: 1 | S9: =IF(R9="","",IFERROR(VLOOKUP(R9, A$9:B$28, 2, FALSE), "No existe")) | T9: 0 | U9: 150000 | V9: =IF(R9="","",T9+U9) | W9: WhatsApp
A10: 2 | B10: Caro Rios | C10: 46098 | D10: 46185 | E10: =IF(C10="","",IF(D10<>"",D10-C10,TODAY()-C10)) | F10: 1000000 | G10: 0.005 | H10: =IF(F10="","",ROUND(F10*(G10/30)*(TODAY()-C10),0)) | I10: =IF(F10="","",IF(D10<>"",ROUND(F10*(G10/30)*(D10-C10),0),"-")) | J10: =IF(F10="","",SUMIF(R$9:R$40, A10, T$9:T$40)) | K10: =IF(F10="","",MAX(0,IF(D10<>"",I10,H10)-J10)) | L10: =IF(F10="","",SUMIF(R$9:R$40, A10, U$9:U$40)) | M10: =IF(F10="","",MAX(0,F10-L10)) | N10: =IF(F10="","",K10+M10) | O10: =IF(F10="","",IF(N10<=0,"PAGADO",IF(D10<>"","PAGADO",IF(E10>30,"PENDIENTE","VIGENTE")))) | Q10: 46094 | R10: 1 | S10: =IF(R10="","",IFERROR(VLOOKUP(R10, A$9:B$28, 2, FALSE), "No existe")) | T10: 0 | U10: 100000 | V10: =IF(R10="","",T10+U10)
A11: 3 | B11: Caro Rios | C11: 46230 | E11: =IF(C11="","",IF(D11<>"",D11-C11,TODAY()-C11)) | F11: 700000 | G11: 0.005 | H11: =IF(F11="","",ROUND(F11*(G11/30)*(TODAY()-C11),0)) | I11: =IF(F11="","",IF(D11<>"",ROUND(F11*(G11/30)*(D11-C11),0),"-")) | J11: =IF(F11="","",SUMIF(R$9:R$40, A11, T$9:T$40)) | K11: =IF(F11="","",MAX(0,IF(D11<>"",I11,H11)-J11)) | L11: =IF(F11="","",SUMIF(R$9:R$40, A11, U$9:U$40)) | M11: =IF(F11="","",MAX(0,F11-L11)) | N11: =IF(F11="","",K11+M11) | O11: =IF(F11="","",IF(N11<=0,"PAGADO",IF(D11<>"","PAGADO",IF(E11>30,"PENDIENTE","VIGENTE")))) | Q11: 46098 | R11: 1 | S11: =IF(R11="","",IFERROR(VLOOKUP(R11, A$9:B$28, 2, FALSE), "No existe")) | T11: 20000 | U11: 150000 | V11: =IF(R11="","",T11+U11)
A12: 4 | B12: Caro Rios | C12: 46277 | E12: =IF(C12="","",IF(D12<>"",D12-C12,TODAY()-C12)) | F12: 300000 | G12: 0.005 | H12: =IF(F12="","",ROUND(F12*(G12/30)*(TODAY()-C12),0)) | I12: =IF(F12="","",IF(D12<>"",ROUND(F12*(G12/30)*(D12-C12),0),"-")) | J12: =IF(F12="","",SUMIF(R$9:R$40, A12, T$9:T$40)) | K12: =IF(F12="","",MAX(0,IF(D12<>"",I12,H12)-J12)) | L12: =IF(F12="","",SUMIF(R$9:R$40, A12, U$9:U$40)) | M12: =IF(F12="","",MAX(0,F12-L12)) | N12: =IF(F12="","",K12+M12) | O12: =IF(F12="","",IF(N12<=0,"PAGADO",IF(D12<>"","PAGADO",IF(E12>30,"PENDIENTE","VIGENTE")))) | Q12: 46111 | R12: 2 | S12: =IF(R12="","",IFERROR(VLOOKUP(R12, A$9:B$28, 2, FALSE), "No existe")) | T12: 10000 | U12: 200000 | V12: =IF(R12="","",T12+U12)
A13: 5 | B13: Caro Rios | E13: =IF(C13="","",IF(D13<>"",D13-C13,TODAY()-C13)) | G13: 0.005 | H13: =IF(F13="","",ROUND(F13*(G13/30)*(TODAY()-C13),0)) | I13: =IF(F13="","",IF(D13<>"",ROUND(F13*(G13/30)*(D13-C13),0),"-")) | J13: =IF(F13="","",SUMIF(R$9:R$40, A13, T$9:T$40)) | K13: =IF(F13="","",MAX(0,IF(D13<>"",I13,H13)-J13)) | L13: =IF(F13="","",SUMIF(R$9:R$40, A13, U$9:U$40)) | M13: =IF(F13="","",MAX(0,F13-L13)) | N13: =IF(F13="","",K13+M13) | O13: =IF(F13="","",IF(N13<=0,"PAGADO",IF(D13<>"","PAGADO",IF(E13>30,"PENDIENTE","VIGENTE")))) | Q13: 46127 | R13: 2 | S13: =IF(R13="","",IFERROR(VLOOKUP(R13, A$9:B$28, 2, FALSE), "No existe")) | T13: 10000 | U13: 200000 | V13: =IF(R13="","",T13+U13)
A14: 6 | B14: Caro Rios | E14: =IF(C14="","",IF(D14<>"",D14-C14,TODAY()-C14)) | G14: 0.005 | H14: =IF(F14="","",ROUND(F14*(G14/30)*(TODAY()-C14),0)) | I14: =IF(F14="","",IF(D14<>"",ROUND(F14*(G14/30)*(D14-C14),0),"-")) | J14: =IF(F14="","",SUMIF(R$9:R$40, A14, T$9:T$40)) | K14: =IF(F14="","",MAX(0,IF(D14<>"",I14,H14)-J14)) | L14: =IF(F14="","",SUMIF(R$9:R$40, A14, U$9:U$40)) | M14: =IF(F14="","",MAX(0,F14-L14)) | N14: =IF(F14="","",K14+M14) | O14: =IF(F14="","",IF(N14<=0,"PAGADO",IF(D14<>"","PAGADO",IF(E14>30,"PENDIENTE","VIGENTE")))) | Q14: 46142 | R14: 2 | S14: =IF(R14="","",IFERROR(VLOOKUP(R14, A$9:B$28, 2, FALSE), "No existe")) | T14: 10000 | U14: 200000 | V14: =IF(R14="","",T14+U14)
A15: 7 | B15: Caro Rios | E15: =IF(C15="","",IF(D15<>"",D15-C15,TODAY()-C15)) | G15: 0.005 | H15: =IF(F15="","",ROUND(F15*(G15/30)*(TODAY()-C15),0)) | I15: =IF(F15="","",IF(D15<>"",ROUND(F15*(G15/30)*(D15-C15),0),"-")) | J15: =IF(F15="","",SUMIF(R$9:R$40, A15, T$9:T$40)) | K15: =IF(F15="","",MAX(0,IF(D15<>"",I15,H15)-J15)) | L15: =IF(F15="","",SUMIF(R$9:R$40, A15, U$9:U$40)) | M15: =IF(F15="","",MAX(0,F15-L15)) | N15: =IF(F15="","",K15+M15) | O15: =IF(F15="","",IF(N15<=0,"PAGADO",IF(D15<>"","PAGADO",IF(E15>30,"PENDIENTE","VIGENTE")))) | Q15: 46157 | R15: 2 | S15: =IF(R15="","",IFERROR(VLOOKUP(R15, A$9:B$28, 2, FALSE), "No existe")) | T15: 10000 | U15: 100000 | V15: =IF(R15="","",T15+U15)
A16: 8 | B16: Caro Rios | E16: =IF(C16="","",IF(D16<>"",D16-C16,TODAY()-C16)) | G16: 0.005 | H16: =IF(F16="","",ROUND(F16*(G16/30)*(TODAY()-C16),0)) | I16: =IF(F16="","",IF(D16<>"",ROUND(F16*(G16/30)*(D16-C16),0),"-")) | J16: =IF(F16="","",SUMIF(R$9:R$40, A16, T$9:T$40)) | K16: =IF(F16="","",MAX(0,IF(D16<>"",I16,H16)-J16)) | L16: =IF(F16="","",SUMIF(R$9:R$40, A16, U$9:U$40)) | M16: =IF(F16="","",MAX(0,F16-L16)) | N16: =IF(F16="","",K16+M16) | O16: =IF(F16="","",IF(N16<=0,"PAGADO",IF(D16<>"","PAGADO",IF(E16>30,"PENDIENTE","VIGENTE")))) | Q16: 46171 | R16: 2 | S16: =IF(R16="","",IFERROR(VLOOKUP(R16, A$9:B$28, 2, FALSE), "No existe")) | T16: 10000 | U16: 100000 | V16: =IF(R16="","",T16+U16)
A17: 9 | B17: Caro Rios | E17: =IF(C17="","",IF(D17<>"",D17-C17,TODAY()-C17)) | G17: 0.005 | H17: =IF(F17="","",ROUND(F17*(G17/30)*(TODAY()-C17),0)) | I17: =IF(F17="","",IF(D17<>"",ROUND(F17*(G17/30)*(D17-C17),0),"-")) | J17: =IF(F17="","",SUMIF(R$9:R$40, A17, T$9:T$40)) | K17: =IF(F17="","",MAX(0,IF(D17<>"",I17,H17)-J17)) | L17: =IF(F17="","",SUMIF(R$9:R$40, A17, U$9:U$40)) | M17: =IF(F17="","",MAX(0,F17-L17)) | N17: =IF(F17="","",K17+M17) | O17: =IF(F17="","",IF(N17<=0,"PAGADO",IF(D17<>"","PAGADO",IF(E17>30,"PENDIENTE","VIGENTE")))) | Q17: 46185 | R17: 2 | S17: =IF(R17="","",IFERROR(VLOOKUP(R17, A$9:B$28, 2, FALSE), "No existe")) | T17: 20000 | U17: 200000 | V17: =IF(R17="","",T17+U17)
A18: 10 | B18: Caro Rios | E18: =IF(C18="","",IF(D18<>"",D18-C18,TODAY()-C18)) | G18: 0.005 | H18: =IF(F18="","",ROUND(F18*(G18/30)*(TODAY()-C18),0)) | I18: =IF(F18="","",IF(D18<>"",ROUND(F18*(G18/30)*(D18-C18),0),"-")) | J18: =IF(F18="","",SUMIF(R$9:R$40, A18, T$9:T$40)) | K18: =IF(F18="","",MAX(0,IF(D18<>"",I18,H18)-J18)) | L18: =IF(F18="","",SUMIF(R$9:R$40, A18, U$9:U$40)) | M18: =IF(F18="","",MAX(0,F18-L18)) | N18: =IF(F18="","",K18+M18) | O18: =IF(F18="","",IF(N18<=0,"PAGADO",IF(D18<>"","PAGADO",IF(E18>30,"PENDIENTE","VIGENTE")))) | Q18: 46236 | R18: 3 | S18: =IF(R18="","",IFERROR(VLOOKUP(R18, A$9:B$28, 2, FALSE), "No existe")) | T18: 0 | U18: 100000 | V18: =IF(R18="","",T18+U18)
A19: 11 | E19: =IF(C19="","",IF(D19<>"",D19-C19,TODAY()-C19)) | G19: 0.005 | H19: =IF(F19="","",ROUND(F19*(G19/30)*(TODAY()-C19),0)) | I19: =IF(F19="","",IF(D19<>"",ROUND(F19*(G19/30)*(D19-C19),0),"-")) | J19: =IF(F19="","",SUMIF(R$9:R$40, A19, T$9:T$40)) | K19: =IF(F19="","",MAX(0,IF(D19<>"",I19,H19)-J19)) | L19: =IF(F19="","",SUMIF(R$9:R$40, A19, U$9:U$40)) | M19: =IF(F19="","",MAX(0,F19-L19)) | N19: =IF(F19="","",K19+M19) | O19: =IF(F19="","",IF(N19<=0,"PAGADO",IF(D19<>"","PAGADO",IF(E19>30,"PENDIENTE","VIGENTE")))) | Q19: 46252 | R19: 3 | S19: =IF(R19="","",IFERROR(VLOOKUP(R19, A$9:B$28, 2, FALSE), "No existe")) | T19: 0 | U19: 100000 | V19: =IF(R19="","",T19+U19)
A20: 12 | E20: =IF(C20="","",IF(D20<>"",D20-C20,TODAY()-C20)) | G20: 0.005 | H20: =IF(F20="","",ROUND(F20*(G20/30)*(TODAY()-C20),0)) | I20: =IF(F20="","",IF(D20<>"",ROUND(F20*(G20/30)*(D20-C20),0),"-")) | J20: =IF(F20="","",SUMIF(R$9:R$40, A20, T$9:T$40)) | K20: =IF(F20="","",MAX(0,IF(D20<>"",I20,H20)-J20)) | L20: =IF(F20="","",SUMIF(R$9:R$40, A20, U$9:U$40)) | M20: =IF(F20="","",MAX(0,F20-L20)) | N20: =IF(F20="","",K20+M20) | O20: =IF(F20="","",IF(N20<=0,"PAGADO",IF(D20<>"","PAGADO",IF(E20>30,"PENDIENTE","VIGENTE")))) | Q20: 46268 | R20: 3 | S20: =IF(R20="","",IFERROR(VLOOKUP(R20, A$9:B$28, 2, FALSE), "No existe")) | T20: 0 | U20: 100000 | V20: =IF(R20="","",T20+U20)
A21: 13 | E21: =IF(C21="","",IF(D21<>"",D21-C21,TODAY()-C21)) | G21: 0.005 | H21: =IF(F21="","",ROUND(F21*(G21/30)*(TODAY()-C21),0)) | I21: =IF(F21="","",IF(D21<>"",ROUND(F21*(G21/30)*(D21-C21),0),"-")) | J21: =IF(F21="","",SUMIF(R$9:R$40, A21, T$9:T$40)) | K21: =IF(F21="","",MAX(0,IF(D21<>"",I21,H21)-J21)) | L21: =IF(F21="","",SUMIF(R$9:R$40, A21, U$9:U$40)) | M21: =IF(F21="","",MAX(0,F21-L21)) | N21: =IF(F21="","",K21+M21) | O21: =IF(F21="","",IF(N21<=0,"PAGADO",IF(D21<>"","PAGADO",IF(E21>30,"PENDIENTE","VIGENTE")))) | Q21: 46280 | R21: 4 | S21: =IF(R21="","",IFERROR(VLOOKUP(R21, A$9:B$28, 2, FALSE), "No existe")) | T21: 0 | U21: 100000 | V21: =IF(R21="","",T21+U21)
A22: 14 | E22: =IF(C22="","",IF(D22<>"",D22-C22,TODAY()-C22)) | G22: 0.005 | H22: =IF(F22="","",ROUND(F22*(G22/30)*(TODAY()-C22),0)) | I22: =IF(F22="","",IF(D22<>"",ROUND(F22*(G22/30)*(D22-C22),0),"-")) | J22: =IF(F22="","",SUMIF(R$9:R$40, A22, T$9:T$40)) | K22: =IF(F22="","",MAX(0,IF(D22<>"",I22,H22)-J22)) | L22: =IF(F22="","",SUMIF(R$9:R$40, A22, U$9:U$40)) | M22: =IF(F22="","",MAX(0,F22-L22)) | N22: =IF(F22="","",K22+M22) | O22: =IF(F22="","",IF(N22<=0,"PAGADO",IF(D22<>"","PAGADO",IF(E22>30,"PENDIENTE","VIGENTE")))) | Q22: 46296 | R22: 4 | S22: =IF(R22="","",IFERROR(VLOOKUP(R22, A$9:B$28, 2, FALSE), "No existe")) | T22: 0 | U22: 100000 | V22: =IF(R22="","",T22+U22)
A23: 15 | E23: =IF(C23="","",IF(D23<>"",D23-C23,TODAY()-C23)) | G23: 0.005 | H23: =IF(F23="","",ROUND(F23*(G23/30)*(TODAY()-C23),0)) | I23: =IF(F23="","",IF(D23<>"",ROUND(F23*(G23/30)*(D23-C23),0),"-")) | J23: =IF(F23="","",SUMIF(R$9:R$40, A23, T$9:T$40)) | K23: =IF(F23="","",MAX(0,IF(D23<>"",I23,H23)-J23)) | L23: =IF(F23="","",SUMIF(R$9:R$40, A23, U$9:U$40)) | M23: =IF(F23="","",MAX(0,F23-L23)) | N23: =IF(F23="","",K23+M23) | O23: =IF(F23="","",IF(N23<=0,"PAGADO",IF(D23<>"","PAGADO",IF(E23>30,"PENDIENTE","VIGENTE")))) | Q23: 46296 | R23: 3 | S23: =IF(R23="","",IFERROR(VLOOKUP(R23, A$9:B$28, 2, FALSE), "No existe")) | T23: 0 | U23: 73767 | V23: =IF(R23="","",T23+U23) | W23: Reclasificacion intereses, se abona a credito 3
A24: 16 | E24: =IF(C24="","",IF(D24<>"",D24-C24,TODAY()-C24)) | G24: 0.005 | H24: =IF(F24="","",ROUND(F24*(G24/30)*(TODAY()-C24),0)) | I24: =IF(F24="","",IF(D24<>"",ROUND(F24*(G24/30)*(D24-C24),0),"-")) | J24: =IF(F24="","",SUMIF(R$9:R$40, A24, T$9:T$40)) | K24: =IF(F24="","",MAX(0,IF(D24<>"",I24,H24)-J24)) | L24: =IF(F24="","",SUMIF(R$9:R$40, A24, U$9:U$40)) | M24: =IF(F24="","",MAX(0,F24-L24)) | N24: =IF(F24="","",K24+M24) | O24: =IF(F24="","",IF(N24<=0,"PAGADO",IF(D24<>"","PAGADO",IF(E24>30,"PENDIENTE","VIGENTE")))) | S24: =IF(R24="","",IFERROR(VLOOKUP(R24, A$9:B$28, 2, FALSE), "No existe")) | V24: =IF(R24="","",T24+U24)
A25: 17 | E25: =IF(C25="","",IF(D25<>"",D25-C25,TODAY()-C25)) | G25: 0.005 | H25: =IF(F25="","",ROUND(F25*(G25/30)*(TODAY()-C25),0)) | I25: =IF(F25="","",IF(D25<>"",ROUND(F25*(G25/30)*(D25-C25),0),"-")) | J25: =IF(F25="","",SUMIF(R$9:R$40, A25, T$9:T$40)) | K25: =IF(F25="","",MAX(0,IF(D25<>"",I25,H25)-J25)) | L25: =IF(F25="","",SUMIF(R$9:R$40, A25, U$9:U$40)) | M25: =IF(F25="","",MAX(0,F25-L25)) | N25: =IF(F25="","",K25+M25) | O25: =IF(F25="","",IF(N25<=0,"PAGADO",IF(D25<>"","PAGADO",IF(E25>30,"PENDIENTE","VIGENTE")))) | S25: =IF(R25="","",IFERROR(VLOOKUP(R25, A$9:B$28, 2, FALSE), "No existe")) | V25: =IF(R25="","",T25+U25)
A26: 18 | E26: =IF(C26="","",IF(D26<>"",D26-C26,TODAY()-C26)) | G26: 0.005 | H26: =IF(F26="","",ROUND(F26*(G26/30)*(TODAY()-C26),0)) | I26: =IF(F26="","",IF(D26<>"",ROUND(F26*(G26/30)*(D26-C26),0),"-")) | J26: =IF(F26="","",SUMIF(R$9:R$40, A26, T$9:T$40)) | K26: =IF(F26="","",MAX(0,IF(D26<>"",I26,H26)-J26)) | L26: =IF(F26="","",SUMIF(R$9:R$40, A26, U$9:U$40)) | M26: =IF(F26="","",MAX(0,F26-L26)) | N26: =IF(F26="","",K26+M26) | O26: =IF(F26="","",IF(N26<=0,"PAGADO",IF(D26<>"","PAGADO",IF(E26>30,"PENDIENTE","VIGENTE")))) | S26: =IF(R26="","",IFERROR(VLOOKUP(R26, A$9:B$28, 2, FALSE), "No existe")) | V26: =IF(R26="","",T26+U26)
A27: 19 | E27: =IF(C27="","",IF(D27<>"",D27-C27,TODAY()-C27)) | G27: 0.005 | H27: =IF(F27="","",ROUND(F27*(G27/30)*(TODAY()-C27),0)) | I27: =IF(F27="","",IF(D27<>"",ROUND(F27*(G27/30)*(D27-C27),0),"-")) | J27: =IF(F27="","",SUMIF(R$9:R$40, A27, T$9:T$40)) | K27: =IF(F27="","",MAX(0,IF(D27<>"",I27,H27)-J27)) | L27: =IF(F27="","",SUMIF(R$9:R$40, A27, U$9:U$40)) | M27: =IF(F27="","",MAX(0,F27-L27)) | N27: =IF(F27="","",K27+M27) | O27: =IF(F27="","",IF(N27<=0,"PAGADO",IF(D27<>"","PAGADO",IF(E27>30,"PENDIENTE","VIGENTE")))) | S27: =IF(R27="","",IFERROR(VLOOKUP(R27, A$9:B$28, 2, FALSE), "No existe")) | V27: =IF(R27="","",T27+U27)
A28: 20 | E28: =IF(C28="","",IF(D28<>"",D28-C28,TODAY()-C28)) | G28: 0.005 | H28: =IF(F28="","",ROUND(F28*(G28/30)*(TODAY()-C28),0)) | I28: =IF(F28="","",IF(D28<>"",ROUND(F28*(G28/30)*(D28-C28),0),"-")) | J28: =IF(F28="","",SUMIF(R$9:R$40, A28, T$9:T$40)) | K28: =IF(F28="","",MAX(0,IF(D28<>"",I28,H28)-J28)) | L28: =IF(F28="","",SUMIF(R$9:R$40, A28, U$9:U$40)) | M28: =IF(F28="","",MAX(0,F28-L28)) | N28: =IF(F28="","",K28+M28) | O28: =IF(F28="","",IF(N28<=0,"PAGADO",IF(D28<>"","PAGADO",IF(E28>30,"PENDIENTE","VIGENTE")))) | S28: =IF(R28="","",IFERROR(VLOOKUP(R28, A$9:B$28, 2, FALSE), "No existe")) | V28: =IF(R28="","",T28+U28)
A29: TOTAL GENERAL CRÉDITOS | F29: =SUM(F9:F28) | H29: =SUM(H9:H28) | I29: =SUM(I9:I28) | J29: =SUM(J9:J28) | K29: =SUM(K9:K28) | L29: =SUM(L9:L28) | M29: =SUM(M9:M28) | N29: =SUM(N9:N28) | S29: =IF(R29="","",IFERROR(VLOOKUP(R29, A$9:B$28, 2, FALSE), "No existe")) | V29: =IF(R29="","",T29+U29)
S30: =IF(R30="","",IFERROR(VLOOKUP(R30, A$9:B$28, 2, FALSE), "No existe")) | V30: =IF(R30="","",T30+U30)
S31: =IF(R31="","",IFERROR(VLOOKUP(R31, A$9:B$28, 2, FALSE), "No existe")) | V31: =IF(R31="","",T31+U31)
S32: =IF(R32="","",IFERROR(VLOOKUP(R32, A$9:B$28, 2, FALSE), "No existe")) | V32: =IF(R32="","",T32+U32)
S33: =IF(R33="","",IFERROR(VLOOKUP(R33, A$9:B$28, 2, FALSE), "No existe")) | V33: =IF(R33="","",T33+U33)
S34: =IF(R34="","",IFERROR(VLOOKUP(R34, A$9:B$28, 2, FALSE), "No existe")) | V34: =IF(R34="","",T34+U34)
S35: =IF(R35="","",IFERROR(VLOOKUP(R35, A$9:B$28, 2, FALSE), "No existe")) | V35: =IF(R35="","",T35+U35)
S36: =IF(R36="","",IFERROR(VLOOKUP(R36, A$9:B$28, 2, FALSE), "No existe")) | V36: =IF(R36="","",T36+U36)
S37: =IF(R37="","",IFERROR(VLOOKUP(R37, A$9:B$28, 2, FALSE), "No existe")) | V37: =IF(R37="","",T37+U37)
S38: =IF(R38="","",IFERROR(VLOOKUP(R38, A$9:B$28, 2, FALSE), "No existe")) | V38: =IF(R38="","",T38+U38)
S39: =IF(R39="","",IFERROR(VLOOKUP(R39, A$9:B$28, 2, FALSE), "No existe")) | V39: =IF(R39="","",T39+U39)
S40: =IF(R40="","",IFERROR(VLOOKUP(R40, A$9:B$28, 2, FALSE), "No existe")) | V40: =IF(R40="","",T40+U40)
Q41: TOTAL ABONOS REGISTRADOS | T41: =SUM(T9:T40) | U41: =SUM(U9:U40) | V41: =SUM(V9:V40)
...

Sheet Andres Castro
A1: 💰 SISTEMA DE CONTROL DE CRÉDITOS, INTERESES CONGELADOS A FECHA DE PAGO Y ABONOS - NATILLERA
A2: Administrador: Santiago | Actualización Automática con =HOY() | Los intereses se congelan a la Fecha de Pago para no seguir acumulando cobros
B3: =HYPERLINK("#Dashboard!A1", "⬅ VOLVER AL DASHBOARD GLOBAL")
B4: FECHA DE HOY | D4: TOTAL PRESTADO | F4: CAPITAL EN LA CALLE | H4: INTERESES A FECHA DE PAGO | J4: INTERESES POR COBRAR | L4: TOTAL POR COBRAR GENERAL | Q4: ABONOS A INTERÉS | S4: ABONOS A CAPITAL | U4: TOTAL RECAUDADO EN ABONOS
B5: =TODAY() | D5: =F19 | F5: =M19 | H5: =I19 | J5: =K19 | L5: =N19 | Q5: =I19 | S5: =L19 | U5: =Q5+S5
A7: 📋 TABLA DE CRÉDITOS Y LIQUIDACIÓN (Con congelamiento de intereses a la fecha de pago) | Q7: 💳 REGISTRO DE ABONOS RECIBIDOS (Permite múltiples pagos por crédito)
A8: N° | B8: Nombre del Socio / Deudor | C8: Fecha Crédito | D8: Fecha Pago / Liquidación | E8: Días | F8: Valor Crédito (Capital) | G8: Tasa Mes | H8: Intereses a Hoy (En Vivo) | I8: Intereses a Fecha Pago | J8: Total Abono Interés | K8: Saldo Interés | L8: Total Abono Capital | M8: Saldo Capital | N8: Total a Pagar Hoy | O8: Estado | Q8: Fecha Pago | R8: N° Crédito | S8: Socio (Automático) | T8: Abono a Intereses | U8: Abono a Capital | V8: Total Abonado | W8: Medio / Comprobante
A9: 1 | B9: Andres Castro | C9: 46239 | E9: =IF(C9="","",IF(D9<>"",D9-C9,TODAY()-C9)) | F9: 2000000 | G9: 0.005 | H9: =IF(F9="","",ROUND(F9*(G9/30)*(TODAY()-C9),0)) | I9: =IF(F9="","",IF(D9<>"",ROUND(F9*(G9/30)*(D9-C9),0),"-")) | J9: =IF(F9="","",SUMIF(R$9:R$19, A9, T$9:T$19)) | K9: =IF(F9="","",MAX(0,IF(D9<>"",I9,H9)-J9)) | L9: =IF(F9="","",SUMIF(R$9:R$19, A9, U$9:U$19)) | M9: =IF(F9="","",MAX(0,F9-L9)) | N9: =IF(F9="","",K9+M9) | O9: =IF(F9="","",IF(N9<=0,"PAGADO",IF(D9<>"","PAGADO",IF(E9>30,"PENDIENTE","VIGENTE")))) | S9: =IF(R9="","",IFERROR(VLOOKUP(R9, A$9:B$18, 2, FALSE), "No existe")) | T9: 0 | V9: =IF(R9="","",T9+U9)
A10: 2 | E10: =IF(C10="","",IF(D10<>"",D10-C10,TODAY()-C10)) | G10: 0.005 | H10: =IF(F10="","",ROUND(F10*(G10/30)*(TODAY()-C10),0)) | I10: =IF(F10="","",IF(D10<>"",ROUND(F10*(G10/30)*(D10-C10),0),"-")) | J10: =IF(F10="","",SUMIF(R$9:R$19, A10, T$9:T$19)) | K10: =IF(F10="","",MAX(0,IF(D10<>"",I10,H10)-J10)) | L10: =IF(F10="","",SUMIF(R$9:R$19, A10, U$9:U$19)) | M10: =IF(F10="","",MAX(0,F10-L10)) | N10: =IF(F10="","",K10+M10) | O10: =IF(F10="","",IF(N10<=0,"PAGADO",IF(D10<>"","PAGADO",IF(E10>30,"PENDIENTE","VIGENTE")))) | S10: =IF(R10="","",IFERROR(VLOOKUP(R10, A$9:B$18, 2, FALSE), "No existe")) | V10: =IF(R10="","",T10+U10)
A11: 3 | E11: =IF(C11="","",IF(D11<>"",D11-C11,TODAY()-C11)) | G11: 0.005 | H11: =IF(F11="","",ROUND(F11*(G11/30)*(TODAY()-C11),0)) | I11: =IF(F11="","",IF(D11<>"",ROUND(F11*(G11/30)*(D11-C11),0),"-")) | J11: =IF(F11="","",SUMIF(R$9:R$19, A11, T$9:T$19)) | K11: =IF(F11="","",MAX(0,IF(D11<>"",I11,H11)-J11)) | L11: =IF(F11="","",SUMIF(R$9:R$19, A11, U$9:U$19)) | M11: =IF(F11="","",MAX(0,F11-L11)) | N11: =IF(F11="","",K11+M11) | O11: =IF(F11="","",IF(N11<=0,"PAGADO",IF(D11<>"","PAGADO",IF(E11>30,"PENDIENTE","VIGENTE")))) | S11: =IF(R11="","",IFERROR(VLOOKUP(R11, A$9:B$18, 2, FALSE), "No existe")) | V11: =IF(R11="","",T11+U11)
A12: 4 | E12: =IF(C12="","",IF(D12<>"",D12-C12,TODAY()-C12)) | G12: 0.005 | H12: =IF(F12="","",ROUND(F12*(G12/30)*(TODAY()-C12),0)) | I12: =IF(F12="","",IF(D12<>"",ROUND(F12*(G12/30)*(D12-C12),0),"-")) | J12: =IF(F12="","",SUMIF(R$9:R$19, A12, T$9:T$19)) | K12: =IF(F12="","",MAX(0,IF(D12<>"",I12,H12)-J12)) | L12: =IF(F12="","",SUMIF(R$9:R$19, A12, U$9:U$19)) | M12: =IF(F12="","",MAX(0,F12-L12)) | N12: =IF(F12="","",K12+M12) | O12: =IF(F12="","",IF(N12<=0,"PAGADO",IF(D12<>"","PAGADO",IF(E12>30,"PENDIENTE","VIGENTE")))) | S12: =IF(R12="","",IFERROR(VLOOKUP(R12, A$9:B$18, 2, FALSE), "No existe")) | V12: =IF(R12="","",T12+U12)
A13: 5 | E13: =IF(C13="","",IF(D13<>"",D13-C13,TODAY()-C13)) | G13: 0.005 | H13: =IF(F13="","",ROUND(F13*(G13/30)*(TODAY()-C13),0)) | I13: =IF(F13="","",IF(D13<>"",ROUND(F13*(G13/30)*(D13-C13),0),"-")) | J13: =IF(F13="","",SUMIF(R$9:R$19, A13, T$9:T$19)) | K13: =IF(F13="","",MAX(0,IF(D13<>"",I13,H13)-J13)) | L13: =IF(F13="","",SUMIF(R$9:R$19, A13, U$9:U$19)) | M13: =IF(F13="","",MAX(0,F13-L13)) | N13: =IF(F13="","",K13+M13) | O13: =IF(F13="","",IF(N13<=0,"PAGADO",IF(D13<>"","PAGADO",IF(E13>30,"PENDIENTE","VIGENTE")))) | S13: =IF(R13="","",IFERROR(VLOOKUP(R13, A$9:B$18, 2, FALSE), "No existe")) | V13: =IF(R13="","",T13+U13)
A14: 6 | E14: =IF(C14="","",IF(D14<>"",D14-C14,TODAY()-C14)) | G14: 0.005 | H14: =IF(F14="","",ROUND(F14*(G14/30)*(TODAY()-C14),0)) | I14: =IF(F14="","",IF(D14<>"",ROUND(F14*(G14/30)*(D14-C14),0),"-")) | J14: =IF(F14="","",SUMIF(R$9:R$19, A14, T$9:T$19)) | K14: =IF(F14="","",MAX(0,IF(D14<>"",I14,H14)-J14)) | L14: =IF(F14="","",SUMIF(R$9:R$19, A14, U$9:U$19)) | M14: =IF(F14="","",MAX(0,F14-L14)) | N14: =IF(F14="","",K14+M14) | O14: =IF(F14="","",IF(N14<=0,"PAGADO",IF(D14<>"","PAGADO",IF(E14>30,"PENDIENTE","VIGENTE")))) | S14: =IF(R14="","",IFERROR(VLOOKUP(R14, A$9:B$18, 2, FALSE), "No existe")) | V14: =IF(R14="","",T14+U14)
A15: 7 | E15: =IF(C15="","",IF(D15<>"",D15-C15,TODAY()-C15)) | G15: 0.005 | H15: =IF(F15="","",ROUND(F15*(G15/30)*(TODAY()-C15),0)) | I15: =IF(F15="","",IF(D15<>"",ROUND(F15*(G15/30)*(D15-C15),0),"-")) | J15: =IF(F15="","",SUMIF(R$9:R$19, A15, T$9:T$19)) | K15: =IF(F15="","",MAX(0,IF(D15<>"",I15,H15)-J15)) | L15: =IF(F15="","",SUMIF(R$9:R$19, A15, U$9:U$19)) | M15: =IF(F15="","",MAX(0,F15-L15)) | N15: =IF(F15="","",K15+M15) | O15: =IF(F15="","",IF(N15<=0,"PAGADO",IF(D15<>"","PAGADO",IF(E15>30,"PENDIENTE","VIGENTE")))) | S15: =IF(R15="","",IFERROR(VLOOKUP(R15, A$9:B$18, 2, FALSE), "No existe")) | V15: =IF(R15="","",T15+U15)
A16: 8 | E16: =IF(C16="","",IF(D16<>"",D16-C16,TODAY()-C16)) | G16: 0.005 | H16: =IF(F16="","",ROUND(F16*(G16/30)*(TODAY()-C16),0)) | I16: =IF(F16="","",IF(D16<>"",ROUND(F16*(G16/30)*(D16-C16),0),"-")) | J16: =IF(F16="","",SUMIF(R$9:R$19, A16, T$9:T$19)) | K16: =IF(F16="","",MAX(0,IF(D16<>"",I16,H16)-J16)) | L16: =IF(F16="","",SUMIF(R$9:R$19, A16, U$9:U$19)) | M16: =IF(F16="","",MAX(0,F16-L16)) | N16: =IF(F16="","",K16+M16) | O16: =IF(F16="","",IF(N16<=0,"PAGADO",IF(D16<>"","PAGADO",IF(E16>30,"PENDIENTE","VIGENTE")))) | S16: =IF(R16="","",IFERROR(VLOOKUP(R16, A$9:B$18, 2, FALSE), "No existe")) | V16: =IF(R16="","",T16+U16)
A17: 9 | E17: =IF(C17="","",IF(D17<>"",D17-C17,TODAY()-C17)) | G17: 0.005 | H17: =IF(F17="","",ROUND(F17*(G17/30)*(TODAY()-C17),0)) | I17: =IF(F17="","",IF(D17<>"",ROUND(F17*(G17/30)*(D17-C17),0),"-")) | J17: =IF(F17="","",SUMIF(R$9:R$19, A17, T$9:T$19)) | K17: =IF(F17="","",MAX(0,IF(D17<>"",I17,H17)-J17)) | L17: =IF(F17="","",SUMIF(R$9:R$19, A17, U$9:U$19)) | M17: =IF(F17="","",MAX(0,F17-L17)) | N17: =IF(F17="","",K17+M17) | O17: =IF(F17="","",IF(N17<=0,"PAGADO",IF(D17<>"","PAGADO",IF(E17>30,"PENDIENTE","VIGENTE")))) | S17: =IF(R17="","",IFERROR(VLOOKUP(R17, A$9:B$18, 2, FALSE), "No existe")) | V17: =IF(R17="","",T17+U17)
A18: 10 | E18: =IF(C18="","",IF(D18<>"",D18-C18,TODAY()-C18)) | G18: 0.005 | H18: =IF(F18="","",ROUND(F18*(G18/30)*(TODAY()-C18),0)) | I18: =IF(F18="","",IF(D18<>"",ROUND(F18*(G18/30)*(D18-C18),0),"-")) | J18: =IF(F18="","",SUMIF(R$9:R$19, A18, T$9:T$19)) | K18: =IF(F18="","",MAX(0,IF(D18<>"",I18,H18)-J18)) | L18: =IF(F18="","",SUMIF(R$9:R$19, A18, U$9:U$19)) | M18: =IF(F18="","",MAX(0,F18-L18)) | N18: =IF(F18="","",K18+M18) | O18: =IF(F18="","",IF(N18<=0,"PAGADO",IF(D18<>"","PAGADO",IF(E18>30,"PENDIENTE","VIGENTE")))) | S18: =IF(R18="","",IFERROR(VLOOKUP(R18, A$9:B$18, 2, FALSE), "No existe")) | V18: =IF(R18="","",T18+U18)
A19: TOTAL GENERAL CRÉDITOS | F19: =SUM(F9:F18) | H19: =SUM(H9:H18) | I19: =SUM(I9:I18) | J19: =SUM(J9:J18) | K19: =SUM(K9:K18) | L19: =SUM(L9:L18) | M19: =SUM(M9:M18) | N19: =SUM(N9:N18) | S19: =IF(R19="","",IFERROR(VLOOKUP(R19, A$9:B$18, 2, FALSE), "No existe")) | V19: =IF(R19="","",T19+U19)
Q20: TOTAL ABONOS REGISTRADOS | T20: =SUM(T9:T19) | U20: =SUM(U9:U19) | V20: =SUM(V9:V19)
A23: 💡 GUÍA DE USO PARA SANTIAGO: CÓMO CONGELAR INTERESES A LA FECHA DE PAGO
A24: ✔ | B24: 1. Casilla 'Fecha Pago / Liquidación' (Columna D): Cuando una persona termine de pagar o liquide el crédito, anotas la fecha exacta en la Columna D. Mientras el crédito siga activo, deja esta casilla vacía.
A25: ✔ | B25: 2. Casilla 'Intereses a Fecha Pago' (Columna I): Al colocar la fecha de pago en la columna D, esta casilla calcula los intereses EXACTOS generados desde la fecha inicial hasta ese día específico, y se CONGELA. Ya no sumará más días ni intereses fantasmas.
A26: ✔ | B26: 3. Casilla 'Intereses a Hoy' (Columna H): Para créditos abiertos (sin fecha de pago), esta casilla sigue corriendo en vivo hasta HOY gracias a la fórmula =HOY(), permitiéndote saber cuánto debe al momento de abrir el archivo.
A27: ✔ | B27: 4. Saldo y Liquidación Definitiva (Columna K): La fórmula del Saldo de Interés detecta automáticamente si el crédito ya se canceló: si tiene fecha de pago, liquida contra los intereses congelados; si está abierto, liquida contra los intereses de hoy.
A28: ✔ | B28: 5. Registro de Múltiples Abonos (Lado Derecho): Todos los abonos parciales (sean 1, 2, 5 o más) se siguen registrando en la tabla derecha (Columnas Q a W) con su fecha y medio de pago, y se suman solos a la izquierda.

Sheet Wilson Alvarez
A1: 💰 SISTEMA DE CONTROL DE CRÉDITOS, INTERESES CONGELADOS A FECHA DE PAGO Y ABONOS - NATILLERA
A2: Administrador: Santiago | Actualización Automática con =HOY() | Los intereses se congelan a la Fecha de Pago para no seguir acumulando cobros
B3: =HYPERLINK("#Dashboard!A1", "⬅ VOLVER AL DASHBOARD GLOBAL")
B4: FECHA DE HOY | D4: TOTAL PRESTADO | F4: CAPITAL EN LA CALLE | H4: INTERESES A FECHA DE PAGO | J4: INTERESES POR COBRAR | L4: TOTAL POR COBRAR GENERAL | Q4: ABONOS A INTERÉS | S4: ABONOS A CAPITAL | U4: TOTAL RECAUDADO EN ABONOS
B5: =TODAY() | D5: =F19 | F5: =M19 | H5: =I19 | J5: =K19 | L5: =N19 | Q5: =I19 | S5: =L19 | U5: =Q5+S5
A7: 📋 TABLA DE CRÉDITOS Y LIQUIDACIÓN (Con congelamiento de intereses a la fecha de pago) | Q7: 💳 REGISTRO DE ABONOS RECIBIDOS (Permite múltiples pagos por crédito)
A8: N° | B8: Nombre del Socio / Deudor | C8: Fecha Crédito | D8: Fecha Pago / Liquidación | E8: Días | F8: Valor Crédito (Capital) | G8: Tasa Mes | H8: Intereses a Hoy (En Vivo) | I8: Intereses a Fecha Pago | J8: Total Abono Interés | K8: Saldo Interés | L8: Total Abono Capital | M8: Saldo Capital | N8: Total a Pagar Hoy | O8: Estado | Q8: Fecha Pago | R8: N° Crédito | S8: Socio (Automático) | T8: Abono a Intereses | U8: Abono a Capital | V8: Total Abonado | W8: Medio / Comprobante
A9: 1 | B9: Andres Castro | C9: 46239 | E9: =IF(C9="","",IF(D9<>"",D9-C9,TODAY()-C9)) | F9: 2000000 | G9: 0.005 | H9: =IF(F9="","",ROUND(F9*(G9/30)*(TODAY()-C9),0)) | I9: =IF(F9="","",IF(D9<>"",ROUND(F9*(G9/30)*(D9-C9),0),"-")) | J9: =IF(F9="","",SUMIF(R$9:R$19, A9, T$9:T$19)) | K9: =IF(F9="","",MAX(0,IF(D9<>"",I9,H9)-J9)) | L9: =IF(F9="","",SUMIF(R$9:R$19, A9, U$9:U$19)) | M9: =IF(F9="","",MAX(0,F9-L9)) | N9: =IF(F9="","",K9+M9) | O9: =IF(F9="","",IF(N9<=0,"PAGADO",IF(D9<>"","PAGADO",IF(E9>30,"PENDIENTE","VIGENTE")))) | S9: =IF(R9="","",IFERROR(VLOOKUP(R9, A$9:B$18, 2, FALSE), "No existe")) | T9: 0 | V9: =IF(R9="","",T9+U9)
A10: 2 | E10: =IF(C10="","",IF(D10<>"",D10-C10,TODAY()-C10)) | G10: 0.005 | H10: =IF(F10="","",ROUND(F10*(G10/30)*(TODAY()-C10),0)) | I10: =IF(F10="","",IF(D10<>"",ROUND(F10*(G10/30)*(D10-C10),0),"-")) | J10: =IF(F10="","",SUMIF(R$9:R$19, A10, T$9:T$19)) | K10: =IF(F10="","",MAX(0,IF(D10<>"",I10,H10)-J10)) | L10: =IF(F10="","",SUMIF(R$9:R$19, A10, U$9:U$19)) | M10: =IF(F10="","",MAX(0,F10-L10)) | N10: =IF(F10="","",K10+M10) | O10: =IF(F10="","",IF(N10<=0,"PAGADO",IF(D10<>"","PAGADO",IF(E10>30,"PENDIENTE","VIGENTE")))) | S10: =IF(R10="","",IFERROR(VLOOKUP(R10, A$9:B$18, 2, FALSE), "No existe")) | V10: =IF(R10="","",T10+U10)
A11: 3 | E11: =IF(C11="","",IF(D11<>"",D11-C11,TODAY()-C11)) | G11: 0.005 | H11: =IF(F11="","",ROUND(F11*(G11/30)*(TODAY()-C11),0)) | I11: =IF(F11="","",IF(D11<>"",ROUND(F11*(G11/30)*(D11-C11),0),"-")) | J11: =IF(F11="","",SUMIF(R$9:R$19, A11, T$9:T$19)) | K11: =IF(F11="","",MAX(0,IF(D11<>"",I11,H11)-J11)) | L11: =IF(F11="","",SUMIF(R$9:R$19, A11, U$9:U$19)) | M11: =IF(F11="","",MAX(0,F11-L11)) | N11: =IF(F11="","",K11+M11) | O11: =IF(F11="","",IF(N11<=0,"PAGADO",IF(D11<>"","PAGADO",IF(E11>30,"PENDIENTE","VIGENTE")))) | S11: =IF(R11="","",IFERROR(VLOOKUP(R11, A$9:B$18, 2, FALSE), "No existe")) | V11: =IF(R11="","",T11+U11)
A12: 4 | E12: =IF(C12="","",IF(D12<>"",D12-C12,TODAY()-C12)) | G12: 0.005 | H12: =IF(F12="","",ROUND(F12*(G12/30)*(TODAY()-C12),0)) | I12: =IF(F12="","",IF(D12<>"",ROUND(F12*(G12/30)*(D12-C12),0),"-")) | J12: =IF(F12="","",SUMIF(R$9:R$19, A12, T$9:T$19)) | K12: =IF(F12="","",MAX(0,IF(D12<>"",I12,H12)-J12)) | L12: =IF(F12="","",SUMIF(R$9:R$19, A12, U$9:U$19)) | M12: =IF(F12="","",MAX(0,F12-L12)) | N12: =IF(F12="","",K12+M12) | O12: =IF(F12="","",IF(N12<=0,"PAGADO",IF(D12<>"","PAGADO",IF(E12>30,"PENDIENTE","VIGENTE")))) | S12: =IF(R12="","",IFERROR(VLOOKUP(R12, A$9:B$18, 2, FALSE), "No existe")) | V12: =IF(R12="","",T12+U12)
A13: 5 | E13: =IF(C13="","",IF(D13<>"",D13-C13,TODAY()-C13)) | G13: 0.005 | H13: =IF(F13="","",ROUND(F13*(G13/30)*(TODAY()-C13),0)) | I13: =IF(F13="","",IF(D13<>"",ROUND(F13*(G13/30)*(D13-C13),0),"-")) | J13: =IF(F13="","",SUMIF(R$9:R$19, A13, T$9:T$19)) | K13: =IF(F13="","",MAX(0,IF(D13<>"",I13,H13)-J13)) | L13: =IF(F13="","",SUMIF(R$9:R$19, A13, U$9:U$19)) | M13: =IF(F13="","",MAX(0,F13-L13)) | N13: =IF(F13="","",K13+M13) | O13: =IF(F13="","",IF(N13<=0,"PAGADO",IF(D13<>"","PAGADO",IF(E13>30,"PENDIENTE","VIGENTE")))) | S13: =IF(R13="","",IFERROR(VLOOKUP(R13, A$9:B$18, 2, FALSE), "No existe")) | V13: =IF(R13="","",T13+U13)
A14: 6 | E14: =IF(C14="","",IF(D14<>"",D14-C14,TODAY()-C14)) | G14: 0.005 | H14: =IF(F14="","",ROUND(F14*(G14/30)*(TODAY()-C14),0)) | I14: =IF(F14="","",IF(D14<>"",ROUND(F14*(G14/30)*(D14-C14),0),"-")) | J14: =IF(F14="","",SUMIF(R$9:R$19, A14, T$9:T$19)) | K14: =IF(F14="","",MAX(0,IF(D14<>"",I14,H14)-J14)) | L14: =IF(F14="","",SUMIF(R$9:R$19, A14, U$9:U$19)) | M14: =IF(F14="","",MAX(0,F14-L14)) | N14: =IF(F14="","",K14+M14) | O14: =IF(F14="","",IF(N14<=0,"PAGADO",IF(D14<>"","PAGADO",IF(E14>30,"PENDIENTE","VIGENTE")))) | S14: =IF(R14="","",IFERROR(VLOOKUP(R14, A$9:B$18, 2, FALSE), "No existe")) | V14: =IF(R14="","",T14+U14)
A15: 7 | E15: =IF(C15="","",IF(D15<>"",D15-C15,TODAY()-C15)) | G15: 0.005 | H15: =IF(F15="","",ROUND(F15*(G15/30)*(TODAY()-C15),0)) | I15: =IF(F15="","",IF(D15<>"",ROUND(F15*(G15/30)*(D15-C15),0),"-")) | J15: =IF(F15="","",SUMIF(R$9:R$19, A15, T$9:T$19)) | K15: =IF(F15="","",MAX(0,IF(D15<>"",I15,H15)-J15)) | L15: =IF(F15="","",SUMIF(R$9:R$19, A15, U$9:U$19)) | M15: =IF(F15="","",MAX(0,F15-L15)) | N15: =IF(F15="","",K15+M15) | O15: =IF(F15="","",IF(N15<=0,"PAGADO",IF(D15<>"","PAGADO",IF(E15>30,"PENDIENTE","VIGENTE")))) | S15: =IF(R15="","",IFERROR(VLOOKUP(R15, A$9:B$18, 2, FALSE), "No existe")) | V15: =IF(R15="","",T15+U15)
A16: 8 | E16: =IF(C16="","",IF(D16<>"",D16-C16,TODAY()-C16)) | G16: 0.005 | H16: =IF(F16="","",ROUND(F16*(G16/30)*(TODAY()-C16),0)) | I16: =IF(F16="","",IF(D16<>"",ROUND(F16*(G16/30)*(D16-C16),0),"-")) | J16: =IF(F16="","",SUMIF(R$9:R$19, A16, T$9:T$19)) | K16: =IF(F16="","",MAX(0,IF(D16<>"",I16,H16)-J16)) | L16: =IF(F16="","",SUMIF(R$9:R$19, A16, U$9:U$19)) | M16: =IF(F16="","",MAX(0,F16-L16)) | N16: =IF(F16="","",K16+M16) | O16: =IF(F16="","",IF(N16<=0,"PAGADO",IF(D16<>"","PAGADO",IF(E16>30,"PENDIENTE","VIGENTE")))) | S16: =IF(R16="","",IFERROR(VLOOKUP(R16, A$9:B$18, 2, FALSE), "No existe")) | V16: =IF(R16="","",T16+U16)
A17: 9 | E17: =IF(C17="","",IF(D17<>"",D17-C17,TODAY()-C17)) | G17: 0.005 | H17: =IF(F17="","",ROUND(F17*(G17/30)*(TODAY()-C17),0)) | I17: =IF(F17="","",IF(D17<>"",ROUND(F17*(G17/30)*(D17-C17),0),"-")) | J17: =IF(F17="","",SUMIF(R$9:R$19, A17, T$9:T$19)) | K17: =IF(F17="","",MAX(0,IF(D17<>"",I17,H17)-J17)) | L17: =IF(F17="","",SUMIF(R$9:R$19, A17, U$9:U$19)) | M17: =IF(F17="","",MAX(0,F17-L17)) | N17: =IF(F17="","",K17+M17) | O17: =IF(F17="","",IF(N17<=0,"PAGADO",IF(D17<>"","PAGADO",IF(E17>30,"PENDIENTE","VIGENTE")))) | S17: =IF(R17="","",IFERROR(VLOOKUP(R17, A$9:B$18, 2, FALSE), "No existe")) | V17: =IF(R17="","",T17+U17)
A18: 10 | E18: =IF(C18="","",IF(D18<>"",D18-C18,TODAY()-C18)) | G18: 0.005 | H18: =IF(F18="","",ROUND(F18*(G18/30)*(TODAY()-C18),0)) | I18: =IF(F18="","",IF(D18<>"",ROUND(F18*(G18/30)*(D18-C18),0),"-")) | J18: =IF(F18="","",SUMIF(R$9:R$19, A18, T$9:T$19)) | K18: =IF(F18="","",MAX(0,IF(D18<>"",I18,H18)-J18)) | L18: =IF(F18="","",SUMIF(R$9:R$19, A18, U$9:U$19)) | M18: =IF(F18="","",MAX(0,F18-L18)) | N18: =IF(F18="","",K18+M18) | O18: =IF(F18="","",IF(N18<=0,"PAGADO",IF(D18<>"","PAGADO",IF(E18>30,"PENDIENTE","VIGENTE")))) | S18: =IF(R18="","",IFERROR(VLOOKUP(R18, A$9:B$18, 2, FALSE), "No existe")) | V18: =IF(R18="","",T18+U18)
A19: TOTAL GENERAL CRÉDITOS | F19: =SUM(F9:F18) | H19: =SUM(H9:H18) | I19: =SUM(I9:I18) | J19: =SUM(J9:J18) | K19: =SUM(K9:K18) | L19: =SUM(L9:L18) | M19: =SUM(M9:M18) | N19: =SUM(N9:N18) | S19: =IF(R19="","",IFERROR(VLOOKUP(R19, A$9:B$18, 2, FALSE), "No existe")) | V19: =IF(R19="","",T19+U19)
Q20: TOTAL ABONOS REGISTRADOS | T20: =SUM(T9:T19) | U20: =SUM(U9:U19) | V20: =SUM(V9:V19)
A23: 💡 GUÍA DE USO PARA SANTIAGO: CÓMO CONGELAR INTERESES A LA FECHA DE PAGO
A24: ✔ | B24: 1. Casilla 'Fecha Pago / Liquidación' (Columna D): Cuando una persona termine de pagar o liquide el crédito, anotas la fecha exacta en la Columna D. Mientras el crédito siga activo, deja esta casilla vacía.
A25: ✔ | B25: 2. Casilla 'Intereses a Fecha Pago' (Columna I): Al colocar la fecha de pago en la columna D, esta casilla calcula los intereses EXACTOS generados desde la fecha inicial hasta ese día específico, y se CONGELA. Ya no sumará más días ni intereses fantasmas.
A26: ✔ | B26: 3. Casilla 'Intereses a Hoy' (Columna H): Para créditos abiertos (sin fecha de pago), esta casilla sigue corriendo en vivo hasta HOY gracias a la fórmula =HOY(), permitiéndote saber cuánto debe al momento de abrir el archivo.
A27: ✔ | B27: 4. Saldo y Liquidación Definitiva (Columna K): La fórmula del Saldo de Interés detecta automáticamente si el crédito ya se canceló: si tiene fecha de pago, liquida contra los intereses congelados; si está abierto, liquida contra los intereses de hoy.
A28: ✔ | B28: 5. Registro de Múltiples Abonos (Lado Derecho): Todos los abonos parciales (sean 1, 2, 5 o más) se siguen registrando en la tabla derecha (Columnas Q a W) con su fecha y medio de pago, y se suman solos a la izquierda.

Sheet Formato Credito Natillera
A1: 💰 SISTEMA DE CONTROL DE CRÉDITOS, INTERESES CONGELADOS A FECHA DE PAGO Y ABONOS - NATILLERA
A2: Administrador: Santiago | Actualización Automática con =HOY() | Los intereses se congelan a la Fecha de Pago para no seguir acumulando cobros
B3: =HYPERLINK("#Dashboard!A1", "⬅ VOLVER AL DASHBOARD GLOBAL")
B4: FECHA DE HOY | D4: TOTAL PRESTADO | F4: CAPITAL EN LA CALLE | H4: INTERESES A FECHA DE PAGO | J4: INTERESES POR COBRAR | L4: TOTAL POR COBRAR GENERAL | Q4: ABONOS A INTERÉS | S4: ABONOS A CAPITAL | U4: TOTAL RECAUDADO EN ABONOS
B5: =TODAY() | D5: =F29 | F5: =M29 | H5: =I29 | J5: =K29 | L5: =N29 | Q5: =J29 | S5: =L29 | U5: =Q5+S5
A7: 📋 TABLA DE CRÉDITOS Y LIQUIDACIÓN (Con congelamiento de intereses a la fecha de pago) | Q7: 💳 REGISTRO DE ABONOS RECIBIDOS (Permite múltiples pagos por crédito)
A8: N° | B8: Nombre del Socio / Deudor | C8: Fecha Crédito | D8: Fecha Pago / Liquidación | E8: Días | F8: Valor Crédito (Capital) | G8: Tasa Mes | H8: Intereses a Hoy (En Vivo) | I8: Intereses a Fecha Pago | J8: Total Abono Interés | K8: Saldo Interés | L8: Total Abono Capital | M8: Saldo Capital | N8: Total a Pagar Hoy | O8: Estado | Q8: Fecha Pago | R8: N° Crédito | S8: Socio (Automático) | T8: Abono a Intereses | U8: Abono a Capital | V8: Total Abonado | W8: Medio / Comprobante
A9: 1 | E9: =IF(C9="","",IF(D9<>"",D9-C9,TODAY()-C9)) | G9: 0.005 | H9: =IF(F9="","",ROUND(F9*(G9/30)*(TODAY()-C9),0)) | I9: =IF(F9="","",IF(D9<>"",ROUND(F9*(G9/30)*(D9-C9),0),"-")) | J9: =IF(F9="","",SUMIF(R$9:R$40, A9, T$9:T$40)) | K9: =IF(F9="","",MAX(0,IF(D9<>"",I9,H9)-J9)) | L9: =IF(F9="","",SUMIF(R$9:R$40, A9, U$9:U$40)) | M9: =IF(F9="","",MAX(0,F9-L9)) | N9: =IF(F9="","",K9+M9) | O9: =IF(F9="","",IF(N9<=0,"PAGADO",IF(D9<>"","PAGADO",IF(E9>30,"PENDIENTE","VIGENTE")))) | S9: =IF(R9="","",IFERROR(VLOOKUP(R9, A$9:B$28, 2, FALSE), "No existe")) | V9: =IF(R9="","",T9+U9)
A10: 2 | E10: =IF(C10="","",IF(D10<>"",D10-C10,TODAY()-C10)) | G10: 0.005 | H10: =IF(F10="","",ROUND(F10*(G10/30)*(TODAY()-C10),0)) | I10: =IF(F10="","",IF(D10<>"",ROUND(F10*(G10/30)*(D10-C10),0),"-")) | J10: =IF(F10="","",SUMIF(R$9:R$40, A10, T$9:T$40)) | K10: =IF(F10="","",MAX(0,IF(D10<>"",I10,H10)-J10)) | L10: =IF(F10="","",SUMIF(R$9:R$40, A10, U$9:U$40)) | M10: =IF(F10="","",MAX(0,F10-L10)) | N10: =IF(F10="","",K10+M10) | O10: =IF(F10="","",IF(N10<=0,"PAGADO",IF(D10<>"","PAGADO",IF(E10>30,"PENDIENTE","VIGENTE")))) | S10: =IF(R10="","",IFERROR(VLOOKUP(R10, A$9:B$28, 2, FALSE), "No existe")) | V10: =IF(R10="","",T10+U10)
A11: 3 | E11: =IF(C11="","",IF(D11<>"",D11-C11,TODAY()-C11)) | G11: 0.005 | H11: =IF(F11="","",ROUND(F11*(G11/30)*(TODAY()-C11),0)) | I11: =IF(F11="","",IF(D11<>"",ROUND(F11*(G11/30)*(D11-C11),0),"-")) | J11: =IF(F11="","",SUMIF(R$9:R$40, A11, T$9:T$40)) | K11: =IF(F11="","",MAX(0,IF(D11<>"",I11,H11)-J11)) | L11: =IF(F11="","",SUMIF(R$9:R$40, A11, U$9:U$40)) | M11: =IF(F11="","",MAX(0,F11-L11)) | N11: =IF(F11="","",K11+M11) | O11: =IF(F11="","",IF(N11<=0,"PAGADO",IF(D11<>"","PAGADO",IF(E11>30,"PENDIENTE","VIGENTE")))) | S11: =IF(R11="","",IFERROR(VLOOKUP(R11, A$9:B$28, 2, FALSE), "No existe")) | V11: =IF(R11="","",T11+U11)
A12: 4 | E12: =IF(C12="","",IF(D12<>"",D12-C12,TODAY()-C12)) | G12: 0.005 | H12: =IF(F12="","",ROUND(F12*(G12/30)*(TODAY()-C12),0)) | I12: =IF(F12="","",IF(D12<>"",ROUND(F12*(G12/30)*(D12-C12),0),"-")) | J12: =IF(F12="","",SUMIF(R$9:R$40, A12, T$9:T$40)) | K12: =IF(F12="","",MAX(0,IF(D12<>"",I12,H12)-J12)) | L12: =IF(F12="","",SUMIF(R$9:R$40, A12, U$9:U$40)) | M12: =IF(F12="","",MAX(0,F12-L12)) | N12: =IF(F12="","",K12+M12) | O12: =IF(F12="","",IF(N12<=0,"PAGADO",IF(D12<>"","PAGADO",IF(E12>30,"PENDIENTE","VIGENTE")))) | S12: =IF(R12="","",IFERROR(VLOOKUP(R12, A$9:B$28, 2, FALSE), "No existe")) | V12: =IF(R12="","",T12+U12)
